<?xml version="1.0" ?>
<robot xmlns:xacro ="http://www.ros.org/wiki/xacro">
<xacro:include filename="$(find chapt6_rob_descrip)/urdf/fishbot/common_inertia.urdf.xacro"/>
    <xacro:macro name="wheel_xacro" params="wheel_name xyz">
        <gazebo reference="${wheel_name}_link">
            <mu1 value="20.0" /><!--切向摩擦系数-->
            <mu2 value="20.0" /><!--法向摩擦系数-->
            <kp value="1000000000.0" /><!--接触刚度-->
            <kd value="1.0" /><!--接触阻尼-->
        </gazebo>
        <link name="${wheel_name}_link">
            <visual>
                <origin xyz="0.0 0.0 0.0" rpy="1.57079 0.0 0.0" />
                <geometry>
                    <cylinder radius="0.032" length="0.04" />
                </geometry>
                <material name="yellow">
                    <color rgba="1.0 1.0 0.0 0.8" />
                </material>
            </visual>
            <collision>
                <origin xyz="0.0 0.0 0.0" rpy="1.57079 0.0 0.0" />
                <geometry>
                    <cylinder radius="0.032" length="0.04" />
                </geometry>
                <material name="yellow">
                    <color rgba="1.0 1.0 0.0 0.8" />
                </material>
            </collision>
            <xacro:cylinder_inertia m="0.05" r="0.032" h="0.04" />
        </link>

        <joint name="${wheel_name}_joint" type="continuous">
            <parent link="base_link"/>
            <child link="${wheel_name}_link"/>
            <origin xyz="${xyz}" rpy="0.0 0.0 0.0"/>
            <axis xyz="0.0 1.0 0.0"/>
            <!-- <limit lower="0.0" upper="0.0" effort="0.0" velocity="0.0"/> -->
        </joint>
    </xacro:macro>

</robot>